Workbook

Sheet Read me
A1: How to use this template
A2: Vltava Market Group · People Analytics · synthetic data
A4: 1. On 'Mapping', add one row per current unit: where does it go, which cost center, who leads it.
A5: 2. Blue cells are yours. Grey cells check your entries as you type: every row must say 'Ready'.
A6: 3. 'Coverage' shows units you haven't mapped yet and whether headcount still adds up.
A7: 4. Send the file to People Analytics. src/reorg_validate.py re-runs these checks and adds spans of control,
A8: management layers and a comparison with the HRIS after go-live.
A10: What the checks catch
A11: ✗ not in target the new unit isn't in the approved target structure (often a typo)
A12: ✗ use CC-… the cost center doesn't belong to that unit
A13: ✗ not found the unit head isn't an active employee
A14: ✗ should be … the effective date differs from the programme date
... A17: This copy is pre-filled with the first HRBP submission, so you can see the flags in action.

Sheet Mapping
A1: Reorganisation mapping: Technology, Q3 2026
A2: Blue cells: you type or pick. Grey cells: checks, don't type. Every row must say 'Ready' before go-live.
A4: Old unit | B4: Old cost center | C4: New division | D4: New unit | E4: New cost center | F4: New unit head (ID) | G4: Head reports to (ID) | H4: Effective date | I4: New unit in target? | J4: Cost center OK? | K4: Head active? | L4: Date OK? | M4: Status
A5: Platform Engineering | B5: =IF(A5="","",IFERROR(_xlfn.XLOOKUP(A5,Lists!$A$5:$A$8,Lists!$C$5:$C$8),"? unknown unit")) | C5: Technology | D5: Platform & Infrastructure | E5: CC-3150 | F5: 100157 | G5: 100100 | H5: 46204 | I5: =IF(D5="","",IF(COUNTIF(Lists!$F$5:$F$7,D5)>0,"✓","✗ not in target")) | J5: =IF(E5="","",IF(COUNTIF(Lists!$F$5:$F$7,D5)=0,"–",IF(_xlfn.XLOOKUP(D5,Lists!$F$5:$F$7,Lists!$G$5:$G$7)=E5,"✓","✗ use "&_xlfn.XLOOKUP(D5,Lists!$F$5:$F$7,Lists!$G$5:$G$7)))) | K5: =IF(F5="","",IF(COUNTIF(People!$A$5:$A$248,F5)>0,"✓","✗ not found")) | L5: =IF(H5="","",IF(H5=Lists!$J$5,"✓","✗ should be "&TEXT(Lists!$J$5,"dd mmm yyyy"))) | M5: =IF(A5="","",IF(COUNTIF(I5:L5,"✗*")=0,"Ready","Fix "&COUNTIF(I5:L5,"✗*")&" issue(s)"))
A6: IT Infrastructure | B6: =IF(A6="","",IFERROR(_xlfn.XLOOKUP(A6,Lists!$A$5:$A$8,Lists!$C$5:$C$8),"? unknown unit")) | C6: Technology | D6: Platform & Infrastucture | E6: CC-3150 | F6: 100101 | G6: 100100 | H6: 46204 | I6: =IF(D6="","",IF(COUNTIF(Lists!$F$5:$F$7,D6)>0,"✓","✗ not in target")) | J6: =IF(E6="","",IF(COUNTIF(Lists!$F$5:$F$7,D6)=0,"–",IF(_xlfn.XLOOKUP(D6,Lists!$F$5:$F$7,Lists!$G$5:$G$7)=E6,"✓","✗ use "&_xlfn.XLOOKUP(D6,Lists!$F$5:$F$7,Lists!$G$5:$G$7)))) | K6: =IF(F6="","",IF(COUNTIF(People!$A$5:$A$248,F6)>0,"✓","✗ not found")) | L6: =IF(H6="","",IF(H6=Lists!$J$5,"✓","✗ should be "&TEXT(Lists!$J$5,"dd mmm yyyy"))) | M6: =IF(A6="","",IF(COUNTIF(I6:L6,"✗*")=0,"Ready","Fix "&COUNTIF(I6:L6,"✗*")&" issue(s)"))
A7: Market Data | B7: =IF(A7="","",IFERROR(_xlfn.XLOOKUP(A7,Lists!$A$5:$A$8,Lists!$C$5:$C$8),"? unknown unit")) | C7: Technology | D7: Data & Analytics | E7: CC-3150 | F7: 100047 | G7: 100100 | H7: 46235 | I7: =IF(D7="","",IF(COUNTIF(Lists!$F$5:$F$7,D7)>0,"✓","✗ not in target")) | J7: =IF(E7="","",IF(COUNTIF(Lists!$F$5:$F$7,D7)=0,"–",IF(_xlfn.XLOOKUP(D7,Lists!$F$5:$F$7,Lists!$G$5:$G$7)=E7,"✓","✗ use "&_xlfn.XLOOKUP(D7,Lists!$F$5:$F$7,Lists!$G$5:$G$7)))) | K7: =IF(F7="","",IF(COUNTIF(People!$A$5:$A$248,F7)>0,"✓","✗ not found")) | L7: =IF(H7="","",IF(H7=Lists!$J$5,"✓","✗ should be "&TEXT(Lists!$J$5,"dd mmm yyyy"))) | M7: =IF(A7="","",IF(COUNTIF(I7:L7,"✗*")=0,"Ready","Fix "&COUNTIF(I7:L7,"✗*")&" issue(s)"))
B8: =IF(A8="","",IFERROR(_xlfn.XLOOKUP(A8,Lists!$A$5:$A$8,Lists!$C$5:$C$8),"? unknown unit")) | I8: =IF(D8="","",IF(COUNTIF(Lists!$F$5:$F$7,D8)>0,"✓","✗ not in target")) | J8: =IF(E8="","",IF(COUNTIF(Lists!$F$5:$F$7,D8)=0,"–",IF(_xlfn.XLOOKUP(D8,Lists!$F$5:$F$7,Lists!$G$5:$G$7)=E8,"✓","✗ use "&_xlfn.XLOOKUP(D8,Lists!$F$5:$F$7,Lists!$G$5:$G$7)))) | K8: =IF(F8="","",IF(COUNTIF(People!$A$5:$A$248,F8)>0,"✓","✗ not found")) | L8: =IF(H8="","",IF(H8=Lists!$J$5,"✓","✗ should be "&TEXT(Lists!$J$5,"dd mmm yyyy"))) | M8: =IF(A8="","",IF(COUNTIF(I8:L8,"✗*")=0,"Ready","Fix "&COUNTIF(I8:L8,"✗*")&" issue(s)"))
B9: =IF(A9="","",IFERROR(_xlfn.XLOOKUP(A9,Lists!$A$5:$A$8,Lists!$C$5:$C$8),"? unknown unit")) | I9: =IF(D9="","",IF(COUNTIF(Lists!$F$5:$F$7,D9)>0,"✓","✗ not in target")) | J9: =IF(E9="","",IF(COUNTIF(Lists!$F$5:$F$7,D9)=0,"–",IF(_xlfn.XLOOKUP(D9,Lists!$F$5:$F$7,Lists!$G$5:$G$7)=E9,"✓","✗ use "&_xlfn.XLOOKUP(D9,Lists!$F$5:$F$7,Lists!$G$5:$G$7)))) | K9: =IF(F9="","",IF(COUNTIF(People!$A$5:$A$248,F9)>0,"✓","✗ not found")) | L9: =IF(H9="","",IF(H9=Lists!$J$5,"✓","✗ should be "&TEXT(Lists!$J$5,"dd mmm yyyy"))) | M9: =IF(A9="","",IF(COUNTIF(I9:L9,"✗*")=0,"Ready","Fix "&COUNTIF(I9:L9,"✗*")&" issue(s)"))
B10: =IF(A10="","",IFERROR(_xlfn.XLOOKUP(A10,Lists!$A$5:$A$8,Lists!$C$5:$C$8),"? unknown unit")) | I10: =IF(D10="","",IF(COUNTIF(Lists!$F$5:$F$7,D10)>0,"✓","✗ not in target")) | J10: =IF(E10="","",IF(COUNTIF(Lists!$F$5:$F$7,D10)=0,"–",IF(_xlfn.XLOOKUP(D10,Lists!$F$5:$F$7,Lists!$G$5:$G$7)=E10,"✓","✗ use "&_xlfn.XLOOKUP(D10,Lists!$F$5:$F$7,Lists!$G$5:$G$7)))) | K10: =IF(F10="","",IF(COUNTIF(People!$A$5:$A$248,F10)>0,"✓","✗ not found")) | L10: =IF(H10="","",IF(H10=Lists!$J$5,"✓","✗ should be "&TEXT(Lists!$J$5,"dd mmm yyyy"))) | M10: =IF(A10="","",IF(COUNTIF(I10:L10,"✗*")=0,"Ready","Fix "&COUNTIF(I10:L10,"✗*")&" issue(s)"))
B11: =IF(A11="","",IFERROR(_xlfn.XLOOKUP(A11,Lists!$A$5:$A$8,Lists!$C$5:$C$8),"? unknown unit")) | I11: =IF(D11="","",IF(COUNTIF(Lists!$F$5:$F$7,D11)>0,"✓","✗ not in target")) | J11: =IF(E11="","",IF(COUNTIF(Lists!$F$5:$F$7,D11)=0,"–",IF(_xlfn.XLOOKUP(D11,Lists!$F$5:$F$7,Lists!$G$5:$G$7)=E11,"✓","✗ use "&_xlfn.XLOOKUP(D11,Lists!$F$5:$F$7,Lists!$G$5:$G$7)))) | K11: =IF(F11="","",IF(COUNTIF(People!$A$5:$A$248,F11)>0,"✓","✗ not found")) | L11: =IF(H11="","",IF(H11=Lists!$J$5,"✓","✗ should be "&TEXT(Lists!$J$5,"dd mmm yyyy"))) | M11: =IF(A11="","",IF(COUNTIF(I11:L11,"✗*")=0,"Ready","Fix "&COUNTIF(I11:L11,"✗*")&" issue(s)"))
B12: =IF(A12="","",IFERROR(_xlfn.XLOOKUP(A12,Lists!$A$5:$A$8,Lists!$C$5:$C$8),"? unknown unit")) | I12: =IF(D12="","",IF(COUNTIF(Lists!$F$5:$F$7,D12)>0,"✓","✗ not in target")) | J12: =IF(E12="","",IF(COUNTIF(Lists!$F$5:$F$7,D12)=0,"–",IF(_xlfn.XLOOKUP(D12,Lists!$F$5:$F$7,Lists!$G$5:$G$7)=E12,"✓","✗ use "&_xlfn.XLOOKUP(D12,Lists!$F$5:$F$7,Lists!$G$5:$G$7)))) | K12: =IF(F12="","",IF(COUNTIF(People!$A$5:$A$248,F12)>0,"✓","✗ not found")) | L12: =IF(H12="","",IF(H12=Lists!$J$5,"✓","✗ should be "&TEXT(Lists!$J$5,"dd mmm yyyy"))) | M12: =IF(A12="","",IF(COUNTIF(I12:L12,"✗*")=0,"Ready","Fix "&COUNTIF(I12:L12,"✗*")&" issue(s)"))
B13: =IF(A13="","",IFERROR(_xlfn.XLOOKUP(A13,Lists!$A$5:$A$8,Lists!$C$5:$C$8),"? unknown unit")) | I13: =IF(D13="","",IF(COUNTIF(Lists!$F$5:$F$7,D13)>0,"✓","✗ not in target")) | J13: =IF(E13="","",IF(COUNTIF(Lists!$F$5:$F$7,D13)=0,"–",IF(_xlfn.XLOOKUP(D13,Lists!$F$5:$F$7,Lists!$G$5:$G$7)=E13,"✓","✗ use "&_xlfn.XLOOKUP(D13,Lists!$F$5:$F$7,Lists!$G$5:$G$7)))) | K13: =IF(F13="","",IF(COUNTIF(People!$A$5:$A$248,F13)>0,"✓","✗ not found")) | L13: =IF(H13="","",IF(H13=Lists!$J$5,"✓","✗ should be "&TEXT(Lists!$J$5,"dd mmm yyyy"))) | M13: =IF(A13="","",IF(COUNTIF(I13:L13,"✗*")=0,"Ready","Fix "&COUNTIF(I13:L13,"✗*")&" issue(s)"))
B14: =IF(A14="","",IFERROR(_xlfn.XLOOKUP(A14,Lists!$A$5:$A$8,Lists!$C$5:$C$8),"? unknown unit")) | I14: =IF(D14="","",IF(COUNTIF(Lists!$F$5:$F$7,D14)>0,"✓","✗ not in target")) | J14: =IF(E14="","",IF(COUNTIF(Lists!$F$5:$F$7,D14)=0,"–",IF(_xlfn.XLOOKUP(D14,Lists!$F$5:$F$7,Lists!$G$5:$G$7)=E14,"✓","✗ use "&_xlfn.XLOOKUP(D14,Lists!$F$5:$F$7,Lists!$G$5:$G$7)))) | K14: =IF(F14="","",IF(COUNTIF(People!$A$5:$A$248,F14)>0,"✓","✗ not found")) | L14: =IF(H14="","",IF(H14=Lists!$J$5,"✓","✗ should be "&TEXT(Lists!$J$5,"dd mmm yyyy"))) | M14: =IF(A14="","",IF(COUNTIF(I14:L14,"✗*")=0,"Ready","Fix "&COUNTIF(I14:L14,"✗*")&" issue(s)"))
B15: =IF(A15="","",IFERROR(_xlfn.XLOOKUP(A15,Lists!$A$5:$A$8,Lists!$C$5:$C$8),"? unknown unit")) | I15: =IF(D15="","",IF(COUNTIF(Lists!$F$5:$F$7,D15)>0,"✓","✗ not in target")) | J15: =IF(E15="","",IF(COUNTIF(Lists!$F$5:$F$7,D15)=0,"–",IF(_xlfn.XLOOKUP(D15,Lists!$F$5:$F$7,Lists!$G$5:$G$7)=E15,"✓","✗ use "&_xlfn.XLOOKUP(D15,Lists!$F$5:$F$7,Lists!$G$5:$G$7)))) | K15: =IF(F15="","",IF(COUNTIF(People!$A$5:$A$248,F15)>0,"✓","✗ not found")) | L15: =IF(H15="","",IF(H15=Lists!$J$5,"✓","✗ should be "&TEXT(Lists!$J$5,"dd mmm yyyy"))) | M15: =IF(A15="","",IF(COUNTIF(I15:L15,"✗*")=0,"Ready","Fix "&COUNTIF(I15:L15,"✗*")&" issue(s)"))
B16: =IF(A16="","",IFERROR(_xlfn.XLOOKUP(A16,Lists!$A$5:$A$8,Lists!$C$5:$C$8),"? unknown unit")) | I16: =IF(D16="","",IF(COUNTIF(Lists!$F$5:$F$7,D16)>0,"✓","✗ not in target")) | J16: =IF(E16="","",IF(COUNTIF(Lists!$F$5:$F$7,D16)=0,"–",IF(_xlfn.XLOOKUP(D16,Lists!$F$5:$F$7,Lists!$G$5:$G$7)=E16,"✓","✗ use "&_xlfn.XLOOKUP(D16,Lists!$F$5:$F$7,Lists!$G$5:$G$7)))) | K16: =IF(F16="","",IF(COUNTIF(People!$A$5:$A$248,F16)>0,"✓","✗ not found")) | L16: =IF(H16="","",IF(H16=Lists!$J$5,"✓","✗ should be "&TEXT(Lists!$J$5,"dd mmm yyyy"))) | M16: =IF(A16="","",IF(COUNTIF(I16:L16,"✗*")=0,"Ready","Fix "&COUNTIF(I16:L16,"✗*")&" issue(s)"))

Sheet Coverage
A1: Coverage check
A2: Every unit in scope must be mapped, and headcount must be the same before and after.
A4: Current unit | B4: Cost center | C4: Positions | D4: Mapped?
A5: =Lists!A5 | B5: =Lists!C5 | C5: =COUNTIF(People!$D$5:$D$248,A5) | D5: =IF(COUNTIF(Mapping!$A$5:$A$16,A5)>0,"✓ mapped","✗ NOT MAPPED")
A6: =Lists!A6 | B6: =Lists!C6 | C6: =COUNTIF(People!$D$5:$D$248,A6) | D6: =IF(COUNTIF(Mapping!$A$5:$A$16,A6)>0,"✓ mapped","✗ NOT MAPPED")
A7: =Lists!A7 | B7: =Lists!C7 | C7: =COUNTIF(People!$D$5:$D$248,A7) | D7: =IF(COUNTIF(Mapping!$A$5:$A$16,A7)>0,"✓ mapped","✗ NOT MAPPED")
A8: =Lists!A8 | B8: =Lists!C8 | C8: =COUNTIF(People!$D$5:$D$248,A8) | D8: =IF(COUNTIF(Mapping!$A$5:$A$16,A8)>0,"✓ mapped","✗ NOT MAPPED")
A10: Positions before | B10: =SUM(C5:C8)
A11: Positions mapped | B11: =SUMIF(D5:D8,"✓ mapped",C5:C8)
A12: Headcount reconciles? | B12: =IF(B10=B11,"✓ yes","✗ "&B10-B11&" positions unmapped")

Sheet Lists
A1: Reference lists
A2: Maintained by People Analytics. Drop-downs and checks read from here.
A4: Current unit | B4: Division | C4: Cost center | D4: Head | F4: Target unit | G4: Target cost center | H4: Target division | J4: Programme date
A5: Market Data | B5: Markets | C5: CC-1300 | D5: 100047 | F5: Platform & Infrastructure | G5: CC-3150 | H5: Technology | J5: 46204
A6: IT Infrastructure | B6: Technology | C6: CC-3200 | D6: 100137 | F6: Data & Analytics | G6: CC-3400 | H6: Technology
A7: Information Security | B7: Technology | C7: CC-3300 | D7: 100292 | F7: Information Security | G7: CC-3300 | H7: Technology
A8: Platform Engineering | B8: Technology | C8: CC-3100 | D8: 100101

Sheet People
A1: Active employees, 30 June 2026
A2: Pseudonymous IDs only (data minimisation). Used to check unit heads.
A4: Person ID | B4: Job title | C4: Manager ID | D4: Department (if in scope)
A5: 100054 | B5: Data Specialist | C5: 100048 | D5: Market Data
A6: 100009 | B6: Markets Specialist | C6: 100007
A7: 100227 | B7: External Consultant | C7: 100007
A8: 100021 | B8: Markets Analyst | C8: 100032
A9: 100176 | B9: Finance Expert | C9: 100170
A10: 100190 | B10: HR Associate | C10: 100186
A11: 100220 | B11: External Consultant | C11: 100104 | D11: Platform Engineering
A12: 100214 | B12: Senior Risk Analyst | C12: 100210
A13: 100195 | B13: HR Analyst | C13: 100186
A14: 100113 | B14: Associate Engineer | C14: 100104 | D14: Platform Engineering
A15: 100040 | B15: Markets Analyst | C15: 100032
A16: 100230 | B16: Operations Analyst | C16: 100076
A17: 100120 | B17: Engineer | C17: 100102 | D17: Platform Engineering
A18: 100114 | B18: Engineer | C18: 100102 | D18: Platform Engineering
A19: 100100 | B19: Head of Technology | C19: 100001 | D19: Platform Engineering
A20: 100109 | B20: Senior Engineer | C20: 100103 | D20: Platform Engineering
A21: 100097 | B21: Operations Analyst | C21: 100088
A22: 100226 | B22: External Consultant | C22: 100076
A23: 100236 | B23: Markets Associate | C23: 100032
A24: 100286 | B24: Engineer | C24: 100102 | D24: Platform Engineering
A25: 100256 | B25: Associate Engineer | C25: 100103 | D25: Platform Engineering
A26: 100285 | B26: Data Associate | C26: 100048 | D26: Market Data
A27: 100160 | B27: Principal Engineer | C27: 100292 | D27: Information Security
A28: 100006 | B28: Team Lead, Trading Services | C28: 100005
A29: 100273 | B29: Compliance Associate | C29: 100198
A30: 100275 | B30: Senior Operations Analyst | C30: 100063
A31: 100261 | B31: Operations Analyst | C31: 100076
A32: 100116 | B32: Senior Engineer | C32: 100104 | D32: Platform Engineering
A33: 100250 | B33: Operations Associate | C33: 100076
A34: 100265 | B34: Engineer | C34: 100103 | D34: Platform Engineering
A35: 100037 | B35: Markets Specialist | C35: 100032
A36: 100130 | B36: Principal Engineer | C36: 100103 | D36: Platform Engineering
A37: 100279 | B37: Operations Associate | C37: 100063
A38: 100030 | B38: Senior Markets Analyst | C38: 100006
A39: 100163 | B39: Senior Engineer | C39: 100292 | D39: Information Security
A40: 100161 | B40: Principal Engineer | C40: 100292 | D40: Information Security
A41: 100150 | B41: Associate Engineer | C41: 100138 | D41: IT Infrastructure
...
